Workbook

Sheet Inputs
A1: Entity 1
B2: Subscriber Management Fee | C2: =SUM(C3:C6) -> 5.27 | D2: Retail Pricing | F2: Start Up Costs (per Brand) | K2: Year 1 Customer Equipment | Y2: Susidy | AB2: Additional Packaged Items
B3: Per service component 1 | C3: 3.37 | D3: Product 1 | E3: =(AD135+BB135)/AY135 -> 0.11296647 | F3: Item | G3: Quantity | H3: Cost Per | I3: Total Cost | K3: Make - Model | L3: Our Cost | M3: Add-Ins (net cost) | N3: Packaging & Shipping | O3: Decorator | P3: Imaging | Q3: Add-Ins (cust price) | R3: Retail Price | S3: Profit | T3: % Penetration | U3: Total Units | V3: Total Cost | W3: Total Rev | X3: Total Profit | Y3: % | AB3: Item | AC3: Cost | AD3: Price | AE3: Pro$F$it (LOSS)
B4: Per service component 2 | C4: 0.35 | D4: Product 2 | E4: =(AE135+BC135)/AZ135 -> 0.11183241 | F4: Component 1 | G4: 5000 | H4: =C16 -> 3.81 | I4: =G4*H4 -> 19050 | L4: 99 | N4: 9 | O4: 5 | P4: =0.85*4 -> 3.4 | R4: =SUM(N4:P4,L4,Q4) -> 116.4 | S4: =Q4+R4-SUM(L4:P4) -> 0 | U4: =T4*$D$39 -> 0 | V4: =U4*L4 -> 0 | W4: =U4*R4 -> 0 | X4: =W4-V4 -> 0 | Y4: =-S4/(SUM(L4,M4,N4,O4,P4)) -> 0
B5: Payment Type Cost | C5: 0.58 | D5: Product 3 | E5: =AF135/BA135 -> 0.1 | F5: Electrical Profile | G5: 1 | H5: 7500 | I5: =G5*H5 -> 7500 | L5: 150 | N5: 9 | O5: 5 | P5: =0.85*4 -> 3.4 | R5: =SUM(N5:P5,L5,Q5) -> 167.4 | S5: =Q5+R5-SUM(L5:P5) -> 0 | U5: =T5*$D$39 -> 0 | V5: =U5*L5 -> 0 | W5: =U5*R5 -> 0 | X5: =W5-V5 -> 0 | Y5: =-S5/(SUM(L5,M5,N5,O5,P5)) -> 0 | AB5: USB Flash Disk | AC5: 28 | AD5: 50 | AE5: =AD5-AC5 -> 22
B6: Customer Care | C6: 0.97 | D6: Product 4 | E6: 0 | F6: Graphical Profile | G6: 0 | H6: 2500 | I6: =G6*H6 -> 0 | L6: 105 | N6: 9 | O6: 5 | P6: =0.85*4 -> 3.4 | R6: =SUM(N6:P6,L6,Q6) -> 122.4 | S6: =Q6+R6-SUM(L6:P6) -> 0 | U6: =T6*$D$39 -> 0 | V6: =U6*L6 -> 0 | W6: =U6*R6 -> 0 | X6: =W6-V6 -> 0 | Y6: =-S6/(SUM(L6,M6,N6,O6,P6)) -> 0
B7: Operational Costs | D7: Various Figures | F7: service component 1 | G7: =G4 -> 5000 | H7: 3.37 | I7: =G7*H7 -> 16850 | L7: 155 | N7: 9 | O7: 5 | P7: =0.85*4 -> 3.4 | R7: =SUM(N7:P7,L7,Q7) -> 172.4 | S7: =Q7+R7-SUM(L7:P7) -> 0 | U7: =T7*$D$39 -> 0 | V7: =U7*L7 -> 0 | W7: =U7*R7 -> 0 | X7: =W7-V7 -> 0 | Y7: =-S7/(SUM(L7,M7,N7,O7,P7)) -> 0
B8: Product 1 | C8: 0.0641 | D8: Longevity (months) | E8: 12 | F8: service component 2 | G8: =G4 -> 5000 | H8: 0.35 | I8: =G8*H8 -> 1750 | L8: 105 | N8: 9 | O8: 5 | P8: =0.85*4 -> 3.4 | R8: =SUM(N8:P8,L8,Q8) -> 122.4 | S8: =Q8+R8-SUM(L8:P8) -> 0 | U8: =T8*$D$39 -> 0 | V8: =U8*L8 -> 0 | W8: =U8*R8 -> 0 | X8: =W8-V8 -> 0 | Y8: =-S8/(SUM(L8,M8,N8,O8,P8)) -> 0
B9: Product 2 | C9: 0.04 | D9: Customer Loss | E9: 0.05 | F9: 1 Month of flat fee | G9: 0 | H9: =C12 -> 1450 | I9: =G9*H9 -> 0 | L9: 39 | N9: 9 | O9: 5 | P9: =0.85*4 -> 3.4 | R9: =SUM(N9:P9,L9,Q9) -> 56.4 | S9: =Q9+R9-SUM(L9:P9) -> 0 | T9: 1 | U9: =T9*$D$39 -> 55869.18 | V9: =U9*L9 -> 2178898 | W9: =U9*R9 -> 3151021.8 | X9: =W9-V9 -> 972123.73 | Y9: =-S9/(SUM(L9,M9,N9,O9,P9)) -> 0
B10: Product 3 | C10: 2 | D10: Daily Service Charge | E10: =1/7 -> 0.14285714 | F10: Pre-purchased product 1 | G10: 0 | H10: =C8 -> 0.0641 | I10: =G10*H10 -> 0 | U10: =T10*$D$39 -> 0 | V10: =U10*L10 -> 0 | W10: =U10*R10 -> 0 | X10: =W10-V10 -> 0 | Y10: =-S10/(SUM(L10,M10,N10,O10,P10)) -> #DIV/0!
B11: Product 1 Commission | C11: 0.15 | D11: Annual Growth Rate (plus 100%) | E11: 1.5 | F11: customer equipment | G11: 0 | H11: =C19 -> 56.4 | I11: =G11*H11 -> 0 | L11: 109 | N11: 10 | O11: 10 | P11: 10 | R11: =SUM(N11:P11,L11,Q11) -> 139 | S11: =Q11+R11-SUM(L11:P11) -> 0 | T11: 0 | U11: =T11*$D$39 -> 0 | V11: =U11*L11 -> 0 | W11: =U11*R11 -> 0 | X11: =W11-V11 -> 0 | Y11: =-S11/(SUM(L11,M11,N11,O11,P11)) -> 0
B12: Monthly Flat Fee | C12: 1450 | F12: equipment branding (physical) | G12: 1 | H12: 1500 | I12: =G12*H12 -> 1500 | L12: 185 | N12: 9 | O12: 5 | P12: =0.85*4 -> 3.4 | R12: =SUM(N12:P12,L12,Q12) -> 202.4 | S12: =Q12+R12-SUM(L12:P12) -> 0 | U12: =T12*$D$39 -> 0 | V12: =U12*L12 -> 0 | W12: =U12*R12 -> 0 | X12: =W12-V12 -> 0 | Y12: =-S12/(SUM(L12,M12,N12,O12,P12)) -> 0
B13: Activation Costs | C13: =SUM(C14:C20) -> 79.63 | D13: Activation Revenue | E13: =SUM(E14:E17) -> 56.4 | F13: software licensing | G13: 0 | H13: 16000 | I13: =G13*H13 -> 0 | L13: 329 | N13: 9 | O13: 5 | P13: =0.85*4 -> 3.4 | R13: =SUM(N13:P13,L13,Q13) -> 346.4 | S13: =Q13+R13-SUM(L13:P13) -> 0 | U13: =T13*$D$39 -> 0 | V13: =U13*L13 -> 0 | W13: =U13*R13 -> 0 | X13: =W13-V13 -> 0 | Y13: =-S13/(SUM(L13,M13,N13,O13,P13)) -> 0
B14: Activation Cost 1 | C14: 0 | D14: Activation Fee | E14: 0 | F14: equipment branding (digital) | G14: 1 | H14: 3000 | I14: =G14*H14 -> 3000 | U14: =T14*$D$39 -> 0 | V14: =U14*L14 -> 0 | W14: =U14*R14 -> 0 | X14: =W14-V14 -> 0 | Y14: =-S14/(SUM(L14,M14,N14,O14,P14)) -> #DIV/0!
B15: Activation Cost 2 | C15: 3 | D15: Customer Equipment | E15: =V20 -> 56.4 | H15: Per-Brand Maximum Setup Cost | I15: =SUM(I4:I14) -> 49650 | U15: =T15*$D$39 -> 0 | V15: =U15*L15 -> 0 | W15: =U15*R15 -> 0 | X15: =W15-V15 -> 0 | Y15: =-S15/(SUM(L15,M15,N15,O15,P15)) -> #DIV/0!
B16: Component | C16: 3.81 | F16: StartUp Costs (One-Time) | U16: =T16*$D$39 -> 0 | V16: =U16*L16 -> 0 | W16: =U16*R16 -> 0 | X16: =W16-V16 -> 0 | Y16: =-S16/(SUM(L16,M16,N16,O16,P16)) -> #DIV/0!
B17: Dealer Commission | C17: 15 | F17: Provisionsing Setup | G17: 1 | H17: 60000 | I17: =G17*H17 -> 60000 | S17: =Q17+R17-SUM(L17:P17) -> 0 | U17: =T17*$D$39 -> 0 | V17: =U17*L17 -> 0 | W17: =U17*R17 -> 0 | X17: =W17-V17 -> 0 | Y17: =-S17/(SUM(L17,M17,N17,O17,P17)) -> #DIV/0!
B18: Payment Processing | C18: 1.42 | D18: Per-Month Cust. Profit | E18: =SUM(F23:F26) -> 18.401398 | F18: Data setup | G18: 1 | H18: 15000 | I18: =G18*H18 -> 15000 | U18: =T18*$D$39 -> 0 | V18: =U18*L18 -> 0 | W18: =U18*R18 -> 0 | X18: =W18-V18 -> 0 | Y18: =-S18/(SUM(L18,M18,N18,O18,P18)) -> #DIV/0!
B19: Customer Equipment | C19: =V20 -> 56.4 | D19: Activation Subsidy | E19: =C13-E13 -> 23.23 | F19: Data Transfer | G19: 1 | H19: 500 | I19: =G19*H19 -> 500 | R19: Totals | S19: =SUM(T4:T18) -> 1 | T19: =SUM(U4:U18) -> 55869.18 | U19: =SUM(V4:V18) -> 2178898 | V19: =SUM(W4:W18) -> 3151021.8 | W19: =SUM(X4:X18) -> 972123.73
D20: Months to Recover Subsidy | E20: =E19/E18 -> 1.2624041 | F20: Application Development | G20: 0.5 | H20: 90000 | I20: =G20*H20 -> 45000 | T20: Averages | U20: =ROUNDDOWN(U19/$D$39,2) -> 39 | V20: =ROUNDDOWN(V19/$D$39,2) -> 56.4 | W20: =ROUNDDOWN(W19/$D$39,2) -> 17.4 | AB20: Total | AC20: =SUM(AC5:AC19) -> 28 | AD20: =SUM(AD5:AD19) -> 50 | AE20: =SUM(AE5:AE19) -> 22
B21: Average Usage | H21: Total One Time Costs | I21: =SUM(I17:I20) -> 120500
C22: Quantity | D22: Revenue | E22: Cost | F22: Profit | K22: Product 3 conversion | L22: 1 | M22: Converted Product 3 | O22: Fully Loaded Costs
B23: Product 1 per user | C23: =ROUNDUP(G39/12/D39,0) -> 229 | D23: =(BB135+AD135)/D39 -> 26.235724 | E23: =C23*C8 -> 14.6789 | F23: =D23-E23 -> 11.556824 | K23: Product 3 conversion | L23: =ROUNDUP(L22/10,0) -> 1 | M23: =C10/1000000*10000 -> 0.02 | P23: Base | Q23: Commission | R23: Customer Management | S23: Flat Operating Fee | T23: Activation (divided by longevity) | U23: Per Unit Charge | V23: Fully Loaded Cost | W23: Retail | X23: Surplus (Deficit)
B24: Product 2 per user | C24: =ROUNDUP(I39/D39/12,0) -> 93 | D24: =(BC135+AE135)/D39 -> 10.547721 | E24: =C24*C9 -> 3.72 | F24: =D24-E24 -> 6.8277214 | G24: Monthly Fixed Revenue | H24: Per Unit Charge | K24: Product 3 billed rate | L24: =C10/L23 -> 2 | O24: Product 1 | P24: =C8 -> 0.0641 | Q24: =C11*E3 -> 0.01694497 | R24: =C2/SUM(C23:C25) -> 0.016355945 | S24: =C12/AY138 -> 7.9424176e-05 | T24: =(C13-E15-E14)/(SUM(C23:C25)*E8) -> 0.0060080424 | U24: =-H25 -> -0.0065979006 | V24: =SUM(P24:U24) -> 0.096890481 | W24: =E3 -> 0.11296647 | X24: =W24-V24 -> 0.016075988
B25: Product 3 per user | C25: =ROUNDDOWN(K39/D39/12,3) -> 0.207 | D25: =AF135/D39 -> 0.020993186 | E25: =C25*M23 -> 0.00414 | F25: =D25-E25 -> 0.016853186 | G25: Average per user | H25: =AI136/SUM(C23:C25) -> 0.0065979006 | I25: ARPU (from chart 1) | J25: Need to drop | O25: Product 2 | P25: =C9 -> 0.04 | R25: =R24 -> 0.016355945 | S25: =S24 -> 7.9424176e-05 | T25: =T24 -> 0.0060080424 | U25: =-H25 -> -0.0065979006 | V25: =SUM(P25:U25) -> 0.055845511 | W25: =E4 -> 0.11183241 | X25: =W25-V25 -> 0.055986899
B26: Product 4 per user | C26: =M39/12/D39 -> 0 | D26: =C26*E6 -> 0 | E26: - | F26: =D26 -> 0 | G26: =AC135/D39 -> 4.3740898 | I26: ='Entity 1 Outputs'!L53 -> 49.637343 | J26: ='Entity 1 Outputs'!D72 -> -3.362657 | O26: Product 3 | P26: =M23 -> 0.02 | R26: =R24 -> 0.016355945 | S26: =S25 -> 7.9424176e-05 | T26: =T25 -> 0.0060080424 | U26: =-H25 -> -0.0065979006 | V26: =SUM(P26:U26) -> 0.035845511 | W26: =E5 -> 0.1 | X26: =W26-V26 -> 0.064154489
B28: Brands | C28: Year 1 Estimates | F28: Monthly | G28: Annual - Aggregate | H28: Monthly | I28: Annual - Aggregate | J28: Monthly Average | K28: Annual - Aggregate | L28: Monthly | M28: Annual - Aggregate
B29: Name | C29: Target Audience | D29: Expected Customers | E29: Penetration Rate | F29: Average Product 1 Sales | G29: Total Product 1 Sales | H29: Average Product 2 Sales | I29: Total Product 2 Sales | J29: Product 3 Sales | K29: Total Product 3 Sales | L29: Average Product 4 | M29: Total Product 4
B30: Brand 1 | C30: 1500000 | D30: 15000 | E30: =D30/C30 -> 0.01 | F30: 229 | G30: =F30*$D30*12 -> 41220000 | H30: 180 | I30: =H30*$D30*12 -> 32400000 | J30: 0.5 | K30: =J30*$D30*12 -> 90000 | L30: 0 | M30: =L30*$D30*12 -> 0
B31: Brand 2 | C31: 328510 | D31: 10000 | E31: =D31/C31 -> 0.030440474 | F31: 229 | G31: =F31*$D31*12 -> 27480000 | H31: 60 | I31: =H31*$D31*12 -> 7200000 | J31: 0.1 | K31: =J31*$D31*12 -> 12000 | L31: 0 | M31: =L31*$D31*12 -> 0
B32: Brand 3 | C32: 895861 | D32: 5000 | E32: =D32/C32 -> 0.005581223 | F32: 229 | G32: =F32*$D32*12 -> 13740000 | H32: 60 | I32: =H32*$D32*12 -> 3600000 | J32: 0.1 | K32: =J32*$D32*12 -> 6000 | L32: 0 | M32: =L32*$D32*12 -> 0
B33: Brand 4 | C33: 1800000 | D33: 5000 | E33: =D33/C33 -> 0.0027777778 | F33: 229 | G33: =F33*$D33*12 -> 13740000 | H33: 60 | I33: =H33*$D33*12 -> 3600000 | J33: 0.1 | K33: =J33*$D33*12 -> 6000 | L33: 0 | M33: =L33*$D33*12 -> 0
B34: Brand 5 | C34: 1066085 | D34: 5000 | E34: =D34/C34 -> 0.0046900575 | F34: 229 | G34: =F34*$D34*12 -> 13740000 | H34: 60 | I34: =H34*$D34*12 -> 3600000 | J34: 0.1 | K34: =J34*$D34*12 -> 6000 | L34: 0 | M34: =L34*$D34*12 -> 0
B35: Brand 6 | C35: 11831495 | D35: 5000 | E35: =D35/C35 -> 0.00042260086 | F35: 229 | G35: =F35*$D35*12 -> 13740000 | H35: 60 | I35: =H35*$D35*12 -> 3600000 | J35: 0.1 | K35: =J35*$D35*12 -> 6000 | L35: 0 | M35: =L35*$D35*12 -> 0
B36: Brand 7 | C36: 86918 | D36: =$E$30*C36 -> 869.18 | E36: =D36/C36 -> 0.01 | F36: 229 | G36: =F36*$D36*12 -> 2388506.6 | H36: 60 | I36: =H36*$D36*12 -> 625809.6 | J36: 0.1 | K36: =J36*$D36*12 -> 1043.016 | L36: 0 | M36: =L36*$D36*12 -> 0
B37: Brand 8 | C37: 18951793 | D37: 5000 | E37: =D37/C37 -> 0.00026382728 | F37: 229 | G37: =F37*$D37*12 -> 13740000 | H37: 60 | I37: =H37*$D37*12 -> 3600000 | J37: 0.1 | K37: =J37*$D37*12 -> 6000 | L37: 0 | M37: =L37*$D37*12 -> 0
B38: Brand 9 | C38: 63786438 | D38: 5000 | E38: =D38/C38 -> 7.8386569e-05 | F38: 229 | G38: =F38*$D38*12 -> 13740000 | H38: 60 | I38: =H38*$D38*12 -> 3600000 | J38: 0.1 | K38: =J38*$D38*12 -> 6000 | L38: 0 | M38: =L38*$D38*12 -> 0
B39: Totals | C39: =SUM(C30:C38) -> 100247100 | D39: =SUM(D30:D38) -> 55869.18 | E39: =D39/C39 -> 0.00055731468 | F39: =G39/$D$39/12 -> 229 | G39: =SUM(G30:G38) -> 1.5352851e+08 | H39: =I39/$D$39/12 -> 92.218121 | I39: =SUM(I30:I38) -> 61825810 | J39: =K39/$D$39/12 -> 0.20739374 | K39: =SUM(K30:K38)*L23 -> 139043.02 | L39: =M39/$D$39/12 -> 0 | M39: =SUM(M30:M38) -> 0
C41: Program Name | D41: Monthly Charge | E41: Product 1 | F41: Product 2 | G41: Product 1 Surplus | H41: Product 2 Surplus | I41: Product 3 | J41: Daily Charge | K41: % of Monthly Fee for Prodcut 1 | L41: % of Monthly fee for Prodcut 2 | M41: % of Monthly Fee for Plan Cost | N41: Price of Prodcut 1 | O41: Price of Product 2 | P41: Total Price of Provided Units | Q41: Price of Plan | R41: Difference | S41: Target | T41: Off-Target
A42: 0.05 | C42: Program 1 | D42: 1e-05 | E42: 0 | F42: 0 | G42: 0.13 | H42: 0.1 | I42: 0.1 | J42: 0.05 | K42: =(E42*G42)/$D42 -> 0 | L42: =(F42*H42)/$D42 -> 0 | M42: =1-K42-L42 -> 1 | N42: =E42*G42 -> 0 | O42: =F42*H42 -> 0 | P42: =N42+O42 -> 0 | Q42: =D42 -> 1e-05 | R42: =P42-Q42 -> -1e-05 | S42: -0.5 | T42: =R42-S42 -> 0.49999
...

Sheet Entity 1 Outputs
A1: Revenues and Costs Based on Plan-Pricing | I1: Fixed Costs and Aggregated Per-Unit Costs | Q1: Itemized Costs | Y1: Loaded Per Unit Costs
A2: Entity 1 | I2: =A2 -> Entity 1 | Q2: =I2 -> Entity 1 | Y2: =Q2 -> Entity 1
A3: Customer Revenue and Costs | I3: =A3 -> Customer Revenue and Costs | Q3: =I3 -> Customer Revenue and Costs | Y3: =Q3 -> Customer Revenue and Costs
A4: Base Case Projection | I4: Base Case Projection | Q4: Base Case Projection | Y4: Base Case Projection
D5: ="Assumes a customer growth rate of "&(Inputs!E11-1)*100&"%" -> Assumes a customer growth rate of 50% | L5: ="Assumes a customer growth rate of "&(Inputs!E11-1)*100&"%" -> Assumes a customer growth rate of 50% | T5: =L5 -> Assumes a customer growth rate of 50% | AB5: =T5 -> Assumes a customer growth rate of 50%
A6: Customers | D6: Year 1 | E6: Year 2 | F6: Year 3 | G6: Year 4 | I6: =A6 -> Customers | L6: =D6 -> Year 1 | M6: =E6 -> Year 2 | N6: =F6 -> Year 3 | O6: =G6 -> Year 4 | Q6: =I6 -> Customers | T6: =L6 -> Year 1 | U6: =M6 -> Year 2 | V6: =N6 -> Year 3 | W6: =O6 -> Year 4 | Y6: =Q6 -> Customers | AB6: =T6 -> Year 1 | AC6: =U6 -> Year 2 | AD6: =V6 -> Year 3 | AE6: =W6 -> Year 4
A7: =Inputs!B30 -> Brand 1 | D7: =Inputs!D30 -> 15000 | E7: =D7*Inputs!$E$11-Inputs!$E$9*D7 -> 21750 | F7: =E7*Inputs!$E$11-Inputs!$E$9*E7 -> 31537.5 | G7: =F7*Inputs!$E$11-Inputs!$E$9*F7 -> 45729.375 | I7: =A7 -> Brand 1 | L7: =Inputs!D30 -> 15000 | M7: =L7*Inputs!$E$11-Inputs!$E$9*L7 -> 21750 | N7: =M7*Inputs!$E$11-Inputs!$E$9*M7 -> 31537.5 | O7: =N7*Inputs!$E$11-Inputs!$E$9*N7 -> 45729.375 | Q7: =I7 -> Brand 1 | T7: =L7 -> 15000 | U7: =M7 -> 21750 | V7: =N7 -> 31537.5 | W7: =O7 -> 45729.375 | Y7: =Q7 -> Brand 1 | AB7: =T7 -> 15000 | AC7: =U7 -> 21750 | AD7: =V7 -> 31537.5 | AE7: =W7 -> 45729.375
A8: =Inputs!B31 -> Brand 2 | D8: =Inputs!D31 -> 10000 | E8: =D8*Inputs!$E$11-Inputs!$E$9*D8 -> 14500 | F8: =E8*Inputs!$E$11-Inputs!$E$9*E8 -> 21025 | G8: =F8*Inputs!$E$11-Inputs!$E$9*F8 -> 30486.25 | I8: =A8 -> Brand 2 | L8: =Inputs!D31 -> 10000 | M8: =L8*Inputs!$E$11-Inputs!$E$9*L8 -> 14500 | N8: =M8*Inputs!$E$11-Inputs!$E$9*M8 -> 21025 | O8: =N8*Inputs!$E$11-Inputs!$E$9*N8 -> 30486.25 | Q8: =I8 -> Brand 2 | T8: =L8 -> 10000 | U8: =M8 -> 14500 | V8: =N8 -> 21025 | W8: =O8 -> 30486.25 | Y8: =Q8 -> Brand 2 | AB8: =T8 -> 10000 | AC8: =U8 -> 14500 | AD8: =V8 -> 21025 | AE8: =W8 -> 30486.25
A9: =Inputs!B32 -> Brand 3 | D9: =Inputs!D32 -> 5000 | E9: =D9*Inputs!$E$11-Inputs!$E$9*D9 -> 7250 | F9: =E9*Inputs!$E$11-Inputs!$E$9*E9 -> 10512.5 | G9: =F9*Inputs!$E$11-Inputs!$E$9*F9 -> 15243.125 | I9: =A9 -> Brand 3 | L9: =Inputs!D32 -> 5000 | M9: =L9*Inputs!$E$11-Inputs!$E$9*L9 -> 7250 | N9: =M9*Inputs!$E$11-Inputs!$E$9*M9 -> 10512.5 | O9: =N9*Inputs!$E$11-Inputs!$E$9*N9 -> 15243.125 | Q9: =I9 -> Brand 3 | T9: =L9 -> 5000 | U9: =M9 -> 7250 | V9: =N9 -> 10512.5 | W9: =O9 -> 15243.125 | Y9: =Q9 -> Brand 3 | AB9: =T9 -> 5000 | AC9: =U9 -> 7250 | AD9: =V9 -> 10512.5 | AE9: =W9 -> 15243.125
A10: =Inputs!B33 -> Brand 4 | D10: =Inputs!D33 -> 5000 | E10: =D10*Inputs!$E$11-Inputs!$E$9*D10 -> 7250 | F10: =E10*Inputs!$E$11-Inputs!$E$9*E10 -> 10512.5 | G10: =F10*Inputs!$E$11-Inputs!$E$9*F10 -> 15243.125 | I10: =A10 -> Brand 4 | L10: =Inputs!D33 -> 5000 | M10: =L10*Inputs!$E$11-Inputs!$E$9*L10 -> 7250 | N10: =M10*Inputs!$E$11-Inputs!$E$9*M10 -> 10512.5 | O10: =N10*Inputs!$E$11-Inputs!$E$9*N10 -> 15243.125 | Q10: =I10 -> Brand 4 | T10: =L10 -> 5000 | U10: =M10 -> 7250 | V10: =N10 -> 10512.5 | W10: =O10 -> 15243.125 | Y10: =Q10 -> Brand 4 | AB10: =T10 -> 5000 | AC10: =U10 -> 7250 | AD10: =V10 -> 10512.5 | AE10: =W10 -> 15243.125
A11: =Inputs!B34 -> Brand 5 | D11: =Inputs!D34 -> 5000 | E11: =D11*Inputs!$E$11-Inputs!$E$9*D11 -> 7250 | F11: =E11*Inputs!$E$11-Inputs!$E$9*E11 -> 10512.5 | G11: =F11*Inputs!$E$11-Inputs!$E$9*F11 -> 15243.125 | I11: =A11 -> Brand 5 | L11: =Inputs!D34 -> 5000 | M11: =L11*Inputs!$E$11-Inputs!$E$9*L11 -> 7250 | N11: =M11*Inputs!$E$11-Inputs!$E$9*M11 -> 10512.5 | O11: =N11*Inputs!$E$11-Inputs!$E$9*N11 -> 15243.125 | Q11: =I11 -> Brand 5 | T11: =L11 -> 5000 | U11: =M11 -> 7250 | V11: =N11 -> 10512.5 | W11: =O11 -> 15243.125 | Y11: =Q11 -> Brand 5 | AB11: =T11 -> 5000 | AC11: =U11 -> 7250 | AD11: =V11 -> 10512.5 | AE11: =W11 -> 15243.125
A12: =Inputs!B35 -> Brand 6 | D12: =Inputs!D35 -> 5000 | E12: =D12*Inputs!$E$11-Inputs!$E$9*D12 -> 7250 | F12: =E12*Inputs!$E$11-Inputs!$E$9*E12 -> 10512.5 | G12: =F12*Inputs!$E$11-Inputs!$E$9*F12 -> 15243.125 | I12: =A12 -> Brand 6 | L12: =Inputs!D35 -> 5000 | M12: =L12*Inputs!$E$11-Inputs!$E$9*L12 -> 7250 | N12: =M12*Inputs!$E$11-Inputs!$E$9*M12 -> 10512.5 | O12: =N12*Inputs!$E$11-Inputs!$E$9*N12 -> 15243.125 | Q12: =I12 -> Brand 6 | T12: =L12 -> 5000 | U12: =M12 -> 7250 | V12: =N12 -> 10512.5 | W12: =O12 -> 15243.125 | Y12: =Q12 -> Brand 6 | AB12: =T12 -> 5000 | AC12: =U12 -> 7250 | AD12: =V12 -> 10512.5 | AE12: =W12 -> 15243.125
A13: =Inputs!B36 -> Brand 7 | D13: =Inputs!D36 -> 869.18 | E13: =D13*Inputs!$E$11-Inputs!$E$9*D13 -> 1260.311 | F13: =E13*Inputs!$E$11-Inputs!$E$9*E13 -> 1827.4509 | G13: =F13*Inputs!$E$11-Inputs!$E$9*F13 -> 2649.8039 | I13: =A13 -> Brand 7 | L13: =Inputs!D36 -> 869.18 | M13: =L13*Inputs!$E$11-Inputs!$E$9*L13 -> 1260.311 | N13: =M13*Inputs!$E$11-Inputs!$E$9*M13 -> 1827.4509 | O13: =N13*Inputs!$E$11-Inputs!$E$9*N13 -> 2649.8039 | Q13: =I13 -> Brand 7 | T13: =L13 -> 869.18 | U13: =M13 -> 1260.311 | V13: =N13 -> 1827.4509 | W13: =O13 -> 2649.8039 | Y13: =Q13 -> Brand 7 | AB13: =T13 -> 869.18 | AC13: =U13 -> 1260.311 | AD13: =V13 -> 1827.4509 | AE13: =W13 -> 2649.8039
A14: =Inputs!B37 -> Brand 8 | D14: =Inputs!D37 -> 5000 | E14: =D14*Inputs!$E$11-Inputs!$E$9*D14 -> 7250 | F14: =E14*Inputs!$E$11-Inputs!$E$9*E14 -> 10512.5 | G14: =F14*Inputs!$E$11-Inputs!$E$9*F14 -> 15243.125 | I14: =A14 -> Brand 8 | L14: =Inputs!D37 -> 5000 | M14: =L14*Inputs!$E$11-Inputs!$E$9*L14 -> 7250 | N14: =M14*Inputs!$E$11-Inputs!$E$9*M14 -> 10512.5 | O14: =N14*Inputs!$E$11-Inputs!$E$9*N14 -> 15243.125 | Q14: =I14 -> Brand 8 | T14: =L14 -> 5000 | U14: =M14 -> 7250 | V14: =N14 -> 10512.5 | W14: =O14 -> 15243.125 | Y14: =Q14 -> Brand 8 | AB14: =T14 -> 5000 | AC14: =U14 -> 7250 | AD14: =V14 -> 10512.5 | AE14: =W14 -> 15243.125
A15: =Inputs!B38 -> Brand 9 | D15: =Inputs!D38 -> 5000 | E15: =D15*Inputs!$E$11-Inputs!$E$9*D15 -> 7250 | F15: =E15*Inputs!$E$11-Inputs!$E$9*E15 -> 10512.5 | G15: =F15*Inputs!$E$11-Inputs!$E$9*F15 -> 15243.125 | I15: =A15 -> Brand 9 | L15: =Inputs!D38 -> 5000 | M15: =L15*Inputs!$E$11-Inputs!$E$9*L15 -> 7250 | N15: =M15*Inputs!$E$11-Inputs!$E$9*M15 -> 10512.5 | O15: =N15*Inputs!$E$11-Inputs!$E$9*N15 -> 15243.125 | Q15: =I15 -> Brand 9 | T15: =L15 -> 5000 | U15: =M15 -> 7250 | V15: =N15 -> 10512.5 | W15: =O15 -> 15243.125 | Y15: =Q15 -> Brand 9 | AB15: =T15 -> 5000 | AC15: =U15 -> 7250 | AD15: =V15 -> 10512.5 | AE15: =W15 -> 15243.125
A16: Total Subscribers* | D16: =ROUNDUP(SUM(D7:D15),0) -> 55870 | E16: =SUM(E7:E15) -> 81010.311 | F16: =SUM(F7:F15) -> 117464.95 | G16: =SUM(G7:G15) -> 170324.18 | I16: Total Subscribers* | L16: =ROUNDUP(SUM(L7:L15),0) -> 55870 | M16: =SUM(M7:M15) -> 81010.311 | N16: =SUM(N7:N15) -> 117464.95 | O16: =SUM(O7:O15) -> 170324.18 | Q16: =I16 -> Total Subscribers* | T16: =SUM(T7:T15) -> 55869.18 | U16: =SUM(U7:U15) -> 81010.311 | V16: =SUM(V7:V15) -> 117464.95 | W16: =SUM(W7:W15) -> 170324.18 | Y16: =Q16 -> Total Subscribers* | AB16: =SUM(AB7:AB15) -> 55869.18 | AC16: =SUM(AC7:AC15) -> 81010.311 | AD16: =SUM(AD7:AD15) -> 117464.95 | AE16: =SUM(AE7:AE15) -> 170324.18
A18: Revenue | B18: NRC | C18: RC | D18: =D6 -> Year 1 | E18: =E6 -> Year 2 | F18: =F6 -> Year 3 | G18: =G6 -> Year 4 | I18: Revenue | J18: NRC | K18: RC | L18: =L6 -> Year 1 | M18: =M6 -> Year 2 | N18: =N6 -> Year 3 | O18: =O6 -> Year 4 | Q18: Revenue | R18: NRC | S18: RC | T18: =T6 -> Year 1 | U18: =U6 -> Year 2 | V18: =V6 -> Year 3 | W18: =W6 -> Year 4 | Y18: Revenue | Z18: NRC | AA18: RC | AB18: =AB6 -> Year 1 | AC18: =AC6 -> Year 2 | AD18: =AD6 -> Year 3 | AE18: =AE6 -> Year 4
A19: Program Fees Revenue** | C19: =Inputs!AC136 -> 4.3130022 | D19: =Inputs!$AC$135/Inputs!$D$39*D16*12 -> 2932564.7 | E19: =Inputs!$AC$135/Inputs!$D$39*E16*12 -> 4252156.5 | F19: =Inputs!$AC$135/Inputs!$D$39*F16*12 -> 6165626.9 | G19: =Inputs!$AC$135/Inputs!$D$39*G16*12 -> 8940159 | I19: =A19 -> Program Fees Revenue** | K19: =C19 -> 4.3130022 | L19: =D19 -> 2932564.7 | M19: =E19 -> 4252156.5 | N19: =F19 -> 6165626.9 | O19: =G19 -> 8940159 | Q19: =I19 -> Program Fees Revenue** | S19: =K19 -> 4.3130022 | T19: =L19 -> 2932564.7 | U19: =M19 -> 4252156.5 | V19: =N19 -> 6165626.9 | W19: =O19 -> 8940159 | Y19: =Q19 -> Program Fees Revenue** | AA19: =S19 -> 4.3130022 | AB19: =T19 -> 2932564.7 | AC19: =U19 -> 4252156.5 | AD19: =V19 -> 6165626.9 | AE19: =W19 -> 8940159
A20: Product 1 Overage Revenue** | C20: =Inputs!AD136 -> 27.52406 | D20: =Inputs!$AD$135/Inputs!$D$39*D16*12 -> 18714595 | E20: =Inputs!$AD$135/Inputs!$D$39*E16*12 -> 27135765 | F20: =Inputs!$AD$135/Inputs!$D$39*F16*12 -> 39346859 | G20: =Inputs!$AD$135/Inputs!$D$39*G16*12 -> 57052945 | I20: =A20 -> Product 1 Overage Revenue** | K20: =C20 -> 27.52406 | L20: =D20 -> 18714595 | M20: =E20 -> 27135765 | N20: =F20 -> 39346859 | O20: =G20 -> 57052945 | Q20: =I20 -> Product 1 Overage Revenue** | S20: =K20 -> 27.52406 | T20: =L20 -> 18714595 | U20: =M20 -> 27135765 | V20: =N20 -> 39346859 | W20: =O20 -> 57052945 | Y20: =Q20 -> Product 1 Overage Revenue** | AA20: =S20 -> 27.52406 | AB20: =T20 -> 18714595 | AC20: =U20 -> 27135765 | AD20: =V20 -> 39346859 | AE20: =W20 -> 57052945
A21: Product 2 Overage Revenue** | C21: =Inputs!AE136 -> 10.400414 | D21: =Inputs!$AE$135/Inputs!$D$39*D16*12 -> 7071614.3 | E21: =Inputs!$AE$135/Inputs!$D$39*E16*12 -> 10253690 | F21: =Inputs!$AE$135/Inputs!$D$39*F16*12 -> 14867851 | G21: =Inputs!$AE$135/Inputs!$D$39*G16*12 -> 21558384 | I21: =A21 -> Product 2 Overage Revenue** | K21: =C21 -> 10.400414 | L21: =D21 -> 7071614.3 | M21: =E21 -> 10253690 | N21: =F21 -> 14867851 | O21: =G21 -> 21558384 | Q21: =I21 -> Product 2 Overage Revenue** | S21: =K21 -> 10.400414 | T21: =L21 -> 7071614.3 | U21: =M21 -> 10253690 | V21: =N21 -> 14867851 | W21: =O21 -> 21558384 | Y21: =Q21 -> Product 2 Overage Revenue** | AA21: =S21 -> 10.400414 | AB21: =T21 -> 7071614.3 | AC21: =U21 -> 10253690 | AD21: =V21 -> 14867851 | AE21: =W21 -> 21558384
A22: Product 3 Usage Revenue** | C22: =Inputs!AF136 -> 0.0207 | D22: =Inputs!$AF$135/Inputs!$D$39*D16*12 -> 14074.672 | E22: =Inputs!$AF$135/Inputs!$D$39*E16*12 -> 20407.975 | F22: =Inputs!$AF$135/Inputs!$D$39*F16*12 -> 29591.563 | G22: =Inputs!$AF$135/Inputs!$D$39*G16*12 -> 42907.767 | I22: =A22 -> Product 3 Usage Revenue** | K22: =C22 -> 0.0207 | L22: =D22 -> 14074.672 | M22: =E22 -> 20407.975 | N22: =F22 -> 29591.563 | O22: =G22 -> 42907.767 | Q22: =I22 -> Product 3 Usage Revenue** | S22: =K22 -> 0.0207 | T22: =L22 -> 14074.672 | U22: =M22 -> 20407.975 | V22: =N22 -> 29591.563 | W22: =O22 -> 42907.767 | Y22: =Q22 -> Product 3 Usage Revenue** | AA22: =S22 -> 0.0207 | AB22: =T22 -> 14074.672 | AC22: =U22 -> 20407.975 | AD22: =V22 -> 29591.563 | AE22: =W22 -> 42907.767
A23: Product 1 "Breakage" Revenue | C23: =Inputs!AG136 -> 1.0359363 | D23: =Inputs!$AG$135/Inputs!$D$39*D16*12 -> 704370.19 | E23: =Inputs!$AG$135/Inputs!$D$39*E16*12 -> 1021321.8 | F23: =Inputs!$AG$135/Inputs!$D$39*F16*12 -> 1480916.6 | G23: =Inputs!$AG$135/Inputs!$D$39*G16*12 -> 2147329.1 | I23: =A23 -> Product 1 "Breakage" Revenue | K23: =C23 -> 1.0359363 | L23: =D23 -> 704370.19 | M23: =E23 -> 1021321.8 | N23: =F23 -> 1480916.6 | O23: =G23 -> 2147329.1 | Q23: =I23 -> Product 1 "Breakage" Revenue | S23: =K23 -> 1.0359363 | T23: =L23 -> 704370.19 | U23: =M23 -> 1021321.8 | V23: =N23 -> 1480916.6 | W23: =O23 -> 2147329.1 | Y23: =Q23 -> Product 1 "Breakage" Revenue | AA23: =S23 -> 1.0359363 | AB23: =T23 -> 704370.19 | AC23: =U23 -> 1021321.8 | AD23: =V23 -> 1480916.6 | AE23: =W23 -> 2147329.1
A24: Product 2 "Breakage" Revenue | C24: =Inputs!AH136 -> 0 | D24: =Inputs!$AH$135/Inputs!$D$39*D16*12 -> 0 | E24: =Inputs!$AH$135/Inputs!$D$39*E16*12 -> 0 | F24: =Inputs!$AH$135/Inputs!$D$39*F16*12 -> 0 | G24: =Inputs!$AH$135/Inputs!$D$39*G16*12 -> 0 | I24: =A24 -> Product 2 "Breakage" Revenue | K24: =C24 -> 0 | L24: =D24 -> 0 | M24: =E24 -> 0 | N24: =F24 -> 0 | O24: =G24 -> 0 | Q24: =I24 -> Product 2 "Breakage" Revenue | S24: =K24 -> 0 | T24: =L24 -> 0 | U24: =M24 -> 0 | V24: =N24 -> 0 | W24: =O24 -> 0 | Y24: =Q24 -> Product 2 "Breakage" Revenue | AA24: =S24 -> 0 | AB24: =T24 -> 0 | AC24: =U24 -> 0 | AD24: =V24 -> 0 | AE24: =W24 -> 0
A25: Daily Charge | C25: =Inputs!AI136 -> 2.1258898 | D25: =Inputs!$AI$135/Inputs!$D$39*D16*12 -> 1445468.6 | E25: =Inputs!$AI$135/Inputs!$D$39*E16*12 -> 2095898.8 | F25: =Inputs!$AI$135/Inputs!$D$39*F16*12 -> 3039053.2 | G25: =Inputs!$AI$135/Inputs!$D$39*G16*12 -> 4406627.2 | I25: =A25 -> Daily Charge | K25: =C25 -> 2.1258898 | L25: =D25 -> 1445468.6 | M25: =E25 -> 2095898.8 | N25: =F25 -> 3039053.2 | O25: =G25 -> 4406627.2 | Q25: =I25 -> Daily Charge | S25: =K25 -> 2.1258898 | T25: =L25 -> 1445468.6 | U25: =M25 -> 2095898.8 | V25: =N25 -> 3039053.2 | W25: =O25 -> 4406627.2 | Y25: =Q25 -> Daily Charge | AA25: =S25 -> 2.1258898 | AB25: =T25 -> 1445468.6 | AC25: =U25 -> 2095898.8 | AD25: =V25 -> 3039053.2 | AE25: =W25 -> 4406627.2
A26: Product 4 | C26: 0.1 | D26: 0 | E26: 0 | F26: 0 | G26: 0 | I26: =A26 -> Product 4 | K26: =C26 -> 0.1 | L26: =D26 -> 0 | M26: =E26 -> 0 | N26: =F26 -> 0 | O26: =G26 -> 0 | Q26: =I26 -> Product 4 | S26: =K26 -> 0.1 | T26: =L26 -> 0 | U26: =M26 -> 0 | V26: =N26 -> 0 | W26: =O26 -> 0 | Y26: =Q26 -> Product 4 | AA26: =S26 -> 0.1 | AB26: =T26 -> 0 | AC26: =U26 -> 0 | AD26: =V26 -> 0 | AE26: =W26 -> 0
A27: Customer Equipment Sales | B27: =Inputs!E15 -> 56.4 | D27: =D$69*$B$27 -> 3151068 | E27: =E69*$B$27 -> 3308554.3 | F27: =F69*$B$27 -> 4797476.5 | G27: =G69*$B$27 -> 6956276.1 | I27: =A27 -> Customer Equipment Sales | J27: =B27 -> 56.4 | L27: =D27 -> 3151068 | M27: =E27 -> 3308554.3 | N27: =F27 -> 4797476.5 | O27: =G27 -> 6956276.1 | Q27: =I27 -> Customer Equipment Sales | R27: =J27 -> 56.4 | T27: =L27 -> 3151068 | U27: =M27 -> 3308554.3 | V27: =N27 -> 4797476.5 | W27: =O27 -> 6956276.1 | Y27: =Q27 -> Customer Equipment Sales | Z27: =R27 -> 56.4 | AB27: =T27 -> 3151068 | AC27: =U27 -> 3308554.3 | AD27: =V27 -> 4797476.5 | AE27: =W27 -> 6956276.1
A28: Customer Activation Fees | B28: =Inputs!E14 -> 0 | D28: =D$69*$B$28 -> 0 | E28: =E$69*$B$28 -> 0 | F28: =F$69*$B$28 -> 0 | G28: =G$69*$B$28 -> 0 | I28: =A28 -> Customer Activation Fees | J28: =B28 -> 0 | L28: =D28 -> 0 | M28: =E28 -> 0 | N28: =F28 -> 0 | O28: =G28 -> 0 | Q28: =I28 -> Customer Activation Fees | R28: =J28 -> 0 | T28: =L28 -> 0 | U28: =M28 -> 0 | V28: =N28 -> 0 | W28: =O28 -> 0 | Y28: =Q28 -> Customer Activation Fees | Z28: =R28 -> 0 | AB28: =T28 -> 0 | AC28: =U28 -> 0 | AD28: =V28 -> 0 | AE28: =W28 -> 0
A29: Total Revenue | D29: =SUM(D19:D28) -> 34033756 | E29: =SUM(E19:E28) -> 48087794 | F29: =SUM(F19:F28) -> 69727374 | G29: =SUM(G19:G28) -> 1.0110463e+08 | I29: =A29 -> Total Revenue | L29: =D29 -> 34033756 | M29: =E29 -> 48087794 | N29: =F29 -> 69727374 | O29: =G29 -> 1.0110463e+08 | Q29: =I29 -> Total Revenue | T29: =L29 -> 34033756 | U29: =M29 -> 48087794 | V29: =N29 -> 69727374 | W29: =O29 -> 1.0110463e+08 | Y29: =Q29 -> Total Revenue | AB29: =T29 -> 34033756 | AC29: =U29 -> 48087794 | AD29: =V29 -> 69727374 | AE29: =W29 -> 1.0110463e+08
A31: Costs (Averaged per User) | B31: NRC | C31: RC | I31: Costs (Per Unit) | J31: NRC | K31: RC | Q31: Itemized Costs | R31: NRC | S31: RC | Y31: Fully Loaded Unit Costs | Z31: NRC | AA31: RC
A32: Branding License Fee | C32: 0.1 | D32: =$C$32*D66 -> 474566.85 | E32: =$C$32*E66 -> 688121.93 | F32: =$C$32*F66 -> 997776.8 | G32: =$C$32*G66 -> 1446776.4 | I32: =A32 -> Branding License Fee | K32: =C32 -> 0.1 | L32: =D32 -> 474566.85 | M32: =E32 -> 688121.93 | N32: =F32 -> 997776.8 | O32: =G32 -> 1446776.4 | Q32: =I32 -> Branding License Fee | S32: =K32 -> 0.1 | T32: =L32 -> 474566.85 | U32: =M32 -> 688121.93 | V32: =N32 -> 997776.8 | W32: =O32 -> 1446776.4 | Y32: =Q32 -> Branding License Fee | AA32: =S32 -> 0.1 | AB32: =T32 -> 474566.85 | AC32: =U32 -> 688121.93 | AD32: =V32 -> 997776.8 | AE32: =W32 -> 1446776.4
A33: Dealer Product 1 Commission | C33: 0.15 | D33: =$C$33*D75 -> 2638421.8 | E33: =$C$33*E75 -> 3825655.5 | F33: =$C$33*F75 -> 5547200.4 | G33: =$C$33*G75 -> 8043440.6 | I33: =A33 -> Dealer Product 1 Commission | K33: =C33 -> 0.15 | L33: =D33 -> 2638421.8 | M33: =E33 -> 3825655.5 | N33: =F33 -> 5547200.4 | O33: =G33 -> 8043440.6 | Q33: =I33 -> Dealer Product 1 Commission | S33: =K33 -> 0.15 | T33: =L33 -> 2638421.8 | U33: =M33 -> 3825655.5 | V33: =N33 -> 5547200.4 | W33: =O33 -> 8043440.6 | Y33: Loaded Product 1 Cost | AA33: =Inputs!V24 -> 0.096890481 | AB33: =$AA33*D77 -> 15086362 | AC33: =$AA33*E77 -> 21874904 | AD33: =$AA33*F77 -> 31718611 | AE33: =$AA33*G77 -> 45991986
A34: Cost of Subscriber Programs | C34: =Inputs!AJ136 -> 9.4493295 | D34: =$C$34*12*D16 -> 6335208.4 | E34: =$C$34*12*E16 -> 9185917.4 | F34: =$C$34*12*F16 -> 13319580 | G34: =$C$34*12*G16 -> 19313391 | I34: Subscriber Management | K34: =Inputs!C2 -> 5.27 | L34: =$K$34*12*L16 -> 3533218.8 | M34: =$K$34*12*M16 -> 5123092.1 | N34: =$K$34*12*N16 -> 7428483.5 | O34: =$K$34*12*O16 -> 10771301 | Q34: =Inputs!B3 -> Per service component 1 | S34: =Inputs!C3 -> 3.37 | T34: =$S$34*12*T16 -> 2259349.6 | U34: =$S$34*12*U16 -> 3276057 | V34: =$S$34*12*V16 -> 4750282.6 | W34: =$S$34*12*W16 -> 6887909.8 | Y34: Loaded Product 2 Cost | AA34: =Inputs!V25 -> 0.055845511 | AB34: =$AA34*D78 -> 3531336.9 | AC34: =$AA34*E78 -> 5120363.3 | AD34: =$AA34*F78 -> 7424526.8 | AE34: =$AA34*G78 -> 10765564
A35: Product 1 Overage Cost | C35: =Inputs!AL136 -> 11.535507 | D35: =$C$35*12*D16 -> 7733865.2 | E35: =$C$35*12*E16 -> 11213940 | F35: =$C$35*12*F16 -> 16260213 | G35: =$C$35*12*G16 -> 23577309 | I35: Product 1 Cost (per unit) | K35: =Inputs!C8 -> 0.0641 | L35: =$K35*Inputs!$C$23*12*L16*(L$16/$L$16) -> 9841321.7 | M35: =$K35*Inputs!$C$23*12*L16*(M$16/$L$16) -> 14269707 | N35: =$K35*Inputs!$C$23*12*L16*(N$16/$L$16) -> 20691075 | O35: =$K35*Inputs!$C$23*12*L16*(O$16/$L$16) -> 30002059 | Q35: =Inputs!B4 -> Per service component 2 | S35: =Inputs!C4 -> 0.35 | T35: =$S$35*12*T16 -> 234650.56 | U35: =$S$35*12*U16 -> 340243.31 | V35: =$S$35*12*V16 -> 493352.79 | W35: =$S$35*12*W16 -> 715361.55 | Y35: Loaded Product 3 Cost | AA35: =Inputs!V26 -> 0.035845511 | AB35: =$AA35*D79 -> 420.42817 | AC35: =$AA35*E79 -> 609.6119 | AD35: =$AA35*F79 -> 883.93726 | AE35: =$AA35*G79 -> 1281.709
A36: Product 2 Overage Cost | C36: =Inputs!AM136 -> 3.72 | D36: =$C$36*12*D16 -> 2494036.8 | E36: =$C$36*12*E16 -> 3616300.3 | F36: =$C$36*12*F16 -> 5243635.4 | G36: =$C$36*12*G16 -> 7603271.3 | I36: Product 2 Cost (per unit) | K36: =Inputs!C9 -> 0.04 | L36: =$K36*Inputs!$C$24*12*$L16*(L$16/$L$16) -> 2494036.8 | M36: =$K36*Inputs!$C$24*12*$L16*(M$16/$L$16) -> 3616300.3 | N36: =$K36*Inputs!$C$24*12*$L16*(N$16/$L$16) -> 5243635.4 | O36: =$K36*Inputs!$C$24*12*$L16*(O$16/$L$16) -> 7603271.3 | Q36: =Inputs!B5 -> Payment Type Cost | S36: =Inputs!C5 -> 0.58 | T36: =$S$36*12*T16 -> 388849.49 | U36: =$S$36*12*U16 -> 563831.76 | V36: =$S$36*12*V16 -> 817556.06 | W36: =$S$36*12*W16 -> 1185456.3 | Y36: =Q49 -> Total Costs | AB36: =SUM(AB32:AB35) -> 19092686 | AC36: =SUM(AC32:AC35) -> 27683999 | AD36: =SUM(AD32:AD35) -> 40141798 | AE36: =SUM(AE32:AE35) -> 58205608
A37: Product 3 Usage Cost | C37: =Inputs!AN136 -> 0.00414 | D37: =$C$37*12*D16 -> 2775.6216 | E37: =$C$37*12*E16 -> 4024.5923 | F37: =$C$37*12*F16 -> 5835.6588 | G37: =$C$37*12*G16 -> 8461.7052 | I37: Product 3 Cost (per unit) | K37: =Inputs!M23 -> 0.02 | L37: =$K37*Inputs!$C$25*12*$L16*(L$16/$L$16) -> 2775.6216 | M37: =$K37*Inputs!$C$25*12*$L16*(M$16/$L$16) -> 4024.5923 | N37: =$K37*Inputs!$C$25*12*$L16*(N$16/$L$16) -> 5835.6588 | O37: =$K37*Inputs!$C$25*12*$L16*(O$16/$L$16) -> 8461.7052 | Q37: =Inputs!B6 -> Customer Care | S37: =Inputs!C6 -> 0.97 | T37: =$S$37*12*T16 -> 650317.26 | U37: =$S$37*12*U16 -> 942960.02 | V37: =$S$37*12*V16 -> 1367292 | W37: =$S$37*12*W16 -> 1982573.4
A38: Product 1 "Breakage" Cost | C38: =Inputs!AO136 -> 1.0359363 | D38: =$C$38*12*D16 -> 694533.11 | E38: =$C$38*12*E16 -> 1007058.2 | F38: =$C$38*12*F16 -> 1460234.4 | G38: =$C$38*12*G16 -> 2117339.9 | I38: =A38 -> Product 1 "Breakage" Cost | K38: =C38 -> 1.0359363 | L38: =D38 -> 694533.11 | M38: =E38 -> 1007058.2 | N38: =F38 -> 1460234.4 | O38: =G38 -> 2117339.9 | Q38: =Inputs!B8 -> Product 1 | S38: =Inputs!C8 -> 0.0641 | T38: =$S38*D77 -> 9980710.2 | U38: =$S38*E77 -> 14471817 | V38: =$S38*F77 -> 20984135 | W38: =$S38*G77 -> 30426996 | Y38: =Q51 -> Total EBITDA | AB38: =AB29-AB36 -> 14941069 | AC38: =AC29-AC36 -> 20403795 | AD38: =AD29-AD36 -> 29585576 | AE38: =AE29-AE36 -> 42899020
A39: Product 2 "Breakage" Cost | C39: =Inputs!AP136 -> 0 | D39: =$C$39*12*D16 -> 0 | E39: =$C$39*12*E16 -> 0 | F39: =$C$39*12*F16 -> 0 | G39: =$C$39*12*G16 -> 0 | I39: =A39 -> Product 2 "Breakage" Cost | K39: =C39 -> 0 | L39: =D39 -> 0 | M39: =E39 -> 0 | N39: =F39 -> 0 | O39: =G39 -> 0 | Q39: =Inputs!B9 -> Product 2 | S39: =Inputs!C9 -> 0.04 | T39: =$S39*D78 -> 2529361.3 | U39: =$S39*E78 -> 3667520.1 | V39: =$S39*F78 -> 5317904.1 | W39: =$S39*G78 -> 7710961
A40: Daily Charge | C40: =Inputs!AQ136 -> 0 | D40: =$C$40*12*D16 -> 0 | E40: =$C$40*12*E16 -> 0 | F40: =$C$40*12*F16 -> 0 | G40: =$C$40*12*G16 -> 0 | I40: =A40 -> Daily Charge | K40: =C40 -> 0 | L40: =D40 -> 0 | M40: =E40 -> 0 | N40: =F40 -> 0 | O40: =G40 -> 0 | Q40: Product 3 (per 10k) | S40: =Inputs!M23 -> 0.02 | T40: =$S40*D79 -> 234.57786 | U40: =$S40*E79 -> 340.13291 | V40: =$S40*F79 -> 493.19272 | W40: =$S40*G79 -> 715.12944 | AB40: Monthly Figurres
A41: Product 4 | C41: 0 | D41: 0 | E41: 0 | F41: 0 | G41: 0 | I41: =A41 -> Product 4 | K41: =C41 -> 0 | L41: =D41 -> 0 | M41: =E41 -> 0 | N41: =F41 -> 0 | O41: =G41 -> 0 | Q41: =Inputs!B12 -> Monthly Flat Fee | S41: =Inputs!C12 -> 1450 | T41: =$S$41*12 -> 17400 | U41: =$S$41*12 -> 17400 | V41: =$S$41*12 -> 17400 | W41: =$S$41*12 -> 17400 | AB41: ARPU | AC41: AVG COST | AD41: Gross margin | AE41: Margin
A42: Customer Equipment Cost | B42: =Inputs!C19 -> 56.4 | D42: =$B$42*D69 -> 3151068 | E42: =$B$42*E69 -> 3308554.3 | F42: =$B$42*F69 -> 4797476.5 | G42: =$B$42*G69 -> 6956276.1 | I42: =A42 -> Customer Equipment Cost | J42: =B42 -> 56.4 | L42: =D42 -> 3151068 | M42: =E42 -> 3308554.3 | N42: =F42 -> 4797476.5 | O42: =G42 -> 6956276.1 | Q42: =Inputs!B14 -> Activation Cost 1 | R42: =Inputs!C14 -> 0 | T42: =$R$42*D$69 -> 0 | U42: =$R$42*E$69 -> 0 | V42: =$R$42*F$69 -> 0 | W42: =$R$42*G$69 -> 0 | AB42: =SUM(AB29:AE29)/SUM(AB16:AE16)/12 -> 49.637439 | AC42: =SUM(AB36:AE36)/SUM(AB16:AE16)/12 -> 28.477909 | AD42: =AB42-AC42 -> 21.15953 | AE42: =AD42/AB42 -> 0.42628166
...

Sheet Entity 2 Out
A1: Fixed Costs and Aggregated Per-Minute Costs | I1: Aggregated Per-Minute Costs | Q1: Itemized Costs
A2: Entity 2 | I2: =A2 -> Entity 2 | Q2: =A2 -> Entity 2
A3: Revenue and Costs | I3: =A3 -> Revenue and Costs | Q3: =A3 -> Revenue and Costs
A4: Base Case Projection | I4: Base Case Projection | Q4: Base Case Projection
D5: ="Assumes a customer growth rate of "&Inputs!E154*100&"%" -> Assumes a customer growth rate of 10% | L5: =D5 -> Assumes a customer growth rate of 10% | T5: =D5 -> Assumes a customer growth rate of 10%
A6: Customers | D6: 2008-2009 | E6: 2009-2010 | F6: 2010-2011 | G6: 2011-2012 | I6: =A6 -> Customers | L6: =D6 -> 2008-2009 | M6: =E6 -> 2009-2010 | N6: =F6 -> 2010-2011 | O6: =G6 -> 2011-2012 | Q6: =I6 -> Customers | T6: 2008-2009 | U6: 2009-2010 | V6: 2010-2011 | W6: 2011-2012
A7: Product 1 | D7: =Inputs!C158 -> 2133333.3 | E7: =D7-E55+E50 -> 2240000 | F7: =E7-F55+F50 -> 2352000 | G7: =F7-G55+G50 -> 2469600 | I7: =A7 -> Product 1 | L7: =D7 -> 2133333.3 | M7: =E7 -> 2240000 | N7: =F7 -> 2352000 | O7: =G7 -> 2469600 | Q7: =I7 -> Product 1 | T7: =D7 -> 2133333.3 | U7: =E7 -> 2240000 | V7: =F7 -> 2352000 | W7: =G7 -> 2469600
A8: Product 2 | D8: =Inputs!D158 -> 266666.67 | E8: =D8-E56+E51 -> 280000 | F8: =E8-F56+F51 -> 294000 | G8: =F8-G56+G51 -> 308700 | I8: =A8 -> Product 2 | L8: =D8 -> 266666.67 | M8: =E8 -> 280000 | N8: =F8 -> 294000 | O8: =G8 -> 308700 | Q8: =I8 -> Product 2 | T8: =D8 -> 266666.67 | U8: =E8 -> 280000 | V8: =F8 -> 294000 | W8: =G8 -> 308700
A9: Product 3 | D9: =Inputs!E158 -> 266666.67 | E9: =D9-E57+E52 -> 280000 | F9: =E9-F57+F52 -> 294000 | G9: =F9-G57+G52 -> 308700 | I9: =A9 -> Product 3 | L9: =D9 -> 266666.67 | M9: =E9 -> 280000 | N9: =F9 -> 294000 | O9: =G9 -> 308700 | Q9: =I9 -> Product 3 | T9: =D9 -> 266666.67 | U9: =E9 -> 280000 | V9: =F9 -> 294000 | W9: =G9 -> 308700
A10: Prodcut 4 | D10: =Inputs!F158 -> 1000000 | E10: =D10-E58+E53 -> 1050000 | F10: =E10-F58+F53 -> 1102500 | G10: =F10-G58+G53 -> 1157625 | I10: =A10 -> Prodcut 4 | L10: =D10 -> 1000000 | M10: =E10 -> 1050000 | N10: =F10 -> 1102500 | O10: =G10 -> 1157625 | Q10: =I10 -> Prodcut 4 | T10: =D10 -> 1000000 | U10: =E10 -> 1050000 | V10: =F10 -> 1102500 | W10: =G10 -> 1157625
A11: Total Subscribers* | D11: =ROUNDUP(SUM(D7:D10),0) -> 3666667 | E11: =SUM(E7:E10) -> 3850000 | F11: =SUM(F7:F10) -> 4042500 | G11: =SUM(G7:G10) -> 4244625 | I11: =A11 -> Total Subscribers* | L11: =ROUNDUP(SUM(L7:L10),0) -> 3666667 | M11: =SUM(M7:M10) -> 3850000 | N11: =SUM(N7:N10) -> 4042500 | O11: =SUM(O7:O10) -> 4244625 | Q11: =I11 -> Total Subscribers* | T11: =SUM(T7:T10) -> 3666666.7 | U11: =SUM(U7:U10) -> 3850000 | V11: =SUM(V7:V10) -> 4042500 | W11: =SUM(W7:W10) -> 4244625
A13: Revenue | B13: NRC | C13: RC | D13: =D6 -> 2008-2009 | E13: =E6 -> 2009-2010 | F13: =F6 -> 2010-2011 | G13: =G6 -> 2011-2012 | I13: =A13 -> Revenue | J13: =B13 -> NRC | K13: =C13 -> RC | L13: =L6 -> 2008-2009 | M13: =M6 -> 2009-2010 | N13: =N6 -> 2010-2011 | O13: =O6 -> 2011-2012 | Q13: =I13 -> Revenue | R13: =B13 -> NRC | S13: =C13 -> RC | T13: =D13 -> 2008-2009 | U13: =E13 -> 2009-2010 | V13: =F13 -> 2010-2011 | W13: =O13 -> 2011-2012
A14: =A7&" Customer Activation" -> Product 1 Customer Activation | B14: =Inputs!C152 -> 29.99 | D14: =D50*$B14 -> 63978667 | E14: =E50*$B14 -> 6397866.7 | F14: =F50*$B14 -> 6717760 | G14: =G50*$B14 -> 7053648 | I14: =A14 -> Product 1 Customer Activation | J14: =B14 -> 29.99 | L14: =D14 -> 63978667 | M14: =E14 -> 6397866.7 | N14: =F14 -> 6717760 | O14: =G14 -> 7053648 | Q14: =I14 -> Product 1 Customer Activation | R14: =B14 -> 29.99 | T14: =D14 -> 63978667 | U14: =E14 -> 6397866.7 | V14: =F14 -> 6717760 | W14: =G14 -> 7053648
A15: =A8&" Customer Activation" -> Product 2 Customer Activation | B15: =Inputs!D152 -> 29.99 | D15: =D51*$B15 -> 7997333.3 | E15: =E51*$B15 -> 799733.33 | F15: =F51*$B15 -> 839720 | G15: =G51*$B15 -> 881706 | I15: =A15 -> Product 2 Customer Activation | J15: =B15 -> 29.99 | L15: =D15 -> 7997333.3 | M15: =E15 -> 799733.33 | N15: =F15 -> 839720 | O15: =G15 -> 881706 | Q15: =I15 -> Product 2 Customer Activation | R15: =B15 -> 29.99 | T15: =D15 -> 7997333.3 | U15: =E15 -> 799733.33 | V15: =F15 -> 839720 | W15: =G15 -> 881706
A16: =A9&" Customer Activation" -> Product 3 Customer Activation | B16: =Inputs!E152 -> 34.99 | D16: =D52*$B16 -> 9330666.7 | E16: =E52*$B16 -> 933066.67 | F16: =F52*$B16 -> 979720 | G16: =G52*$B16 -> 1028706 | I16: =A16 -> Product 3 Customer Activation | J16: =B16 -> 34.99 | L16: =D16 -> 9330666.7 | M16: =E16 -> 933066.67 | N16: =F16 -> 979720 | O16: =G16 -> 1028706 | Q16: =I16 -> Product 3 Customer Activation | R16: =B16 -> 34.99 | T16: =D16 -> 9330666.7 | U16: =E16 -> 933066.67 | V16: =F16 -> 979720 | W16: =G16 -> 1028706
A17: =A10&" Customer Activation" -> Prodcut 4 Customer Activation | B17: =Inputs!F152 -> 44.95 | D17: =D53*$B17 -> 44950000 | E17: =E53*$B17 -> 4495000 | F17: =F53*$B17 -> 4719750 | G17: =G53*$B17 -> 4955737.5 | I17: =A17 -> Prodcut 4 Customer Activation | J17: =B17 -> 44.95 | L17: =D17 -> 44950000 | M17: =E17 -> 4495000 | N17: =F17 -> 4719750 | O17: =G17 -> 4955737.5 | Q17: =I17 -> Prodcut 4 Customer Activation | R17: =B17 -> 44.95 | T17: =D17 -> 44950000 | U17: =E17 -> 4495000 | V17: =F17 -> 4719750 | W17: =G17 -> 4955737.5
A18: =A7&" Usage" -> Product 1 Usage | C18: =Inputs!C153 -> 19.95 | D18: =12*D7*$C18 -> 5.1072e+08 | E18: =12*E7*$C18 -> 5.36256e+08 | F18: =12*F7*$C18 -> 5.630688e+08 | G18: =12*G7*$C18 -> 5.9122224e+08 | I18: =A18 -> Product 1 Usage | K18: =C18 -> 19.95 | L18: =D18 -> 5.1072e+08 | M18: =E18 -> 5.36256e+08 | N18: =F18 -> 5.630688e+08 | O18: =G18 -> 5.9122224e+08 | Q18: =I18 -> Product 1 Usage | S18: =C18 -> 19.95 | T18: =D18 -> 5.1072e+08 | U18: =E18 -> 5.36256e+08 | V18: =F18 -> 5.630688e+08 | W18: =G18 -> 5.9122224e+08
A19: =A8&" Usage" -> Product 2 Usage | C19: =Inputs!D153 -> 14.95 | D19: =12*D8*$C19 -> 47840000 | E19: =12*E8*$C19 -> 50232000 | F19: =12*F8*$C19 -> 52743600 | G19: =12*G8*$C19 -> 55380780 | I19: =A19 -> Product 2 Usage | K19: =C19 -> 14.95 | L19: =D19 -> 47840000 | M19: =E19 -> 50232000 | N19: =F19 -> 52743600 | O19: =G19 -> 55380780 | Q19: =I19 -> Product 2 Usage | S19: =C19 -> 14.95 | T19: =D19 -> 47840000 | U19: =E19 -> 50232000 | V19: =F19 -> 52743600 | W19: =G19 -> 55380780
A20: =A9&" Usage" -> Product 3 Usage | C20: =Inputs!E153 -> 9.95 | D20: =12*D9*$C20 -> 31840000 | E20: =12*E9*$C20 -> 33432000 | F20: =12*F9*$C20 -> 35103600 | G20: =12*G9*$C20 -> 36858780 | I20: =A20 -> Product 3 Usage | K20: =C20 -> 9.95 | L20: =D20 -> 31840000 | M20: =E20 -> 33432000 | N20: =F20 -> 35103600 | O20: =G20 -> 36858780 | Q20: =I20 -> Product 3 Usage | S20: =C20 -> 9.95 | T20: =D20 -> 31840000 | U20: =E20 -> 33432000 | V20: =F20 -> 35103600 | W20: =G20 -> 36858780
A21: =A10&" Usage" -> Prodcut 4 Usage | C21: =Inputs!F153 -> 44.95 | D21: =12*D10*$C21 -> 539400000 | E21: =12*E10*$C21 -> 566370000 | F21: =12*F10*$C21 -> 594688500 | G21: =12*G10*$C21 -> 624422925 | I21: =A21 -> Prodcut 4 Usage | K21: =C21 -> 44.95 | L21: =D21 -> 539400000 | M21: =E21 -> 566370000 | N21: =F21 -> 594688500 | O21: =G21 -> 624422925 | Q21: =I21 -> Prodcut 4 Usage | S21: =C21 -> 44.95 | T21: =D21 -> 539400000 | U21: =E21 -> 566370000 | V21: =F21 -> 594688500 | W21: =G21 -> 624422925
A22: Equipment Sales | D22: =D58*$B22 -> 0 | E22: =E58*$B22 -> 0 | F22: =F58*$B22 -> 0 | G22: =G58*$B22 -> 0 | I22: =A22 -> Equipment Sales | J22: =B22 -> 0 | L22: =D22 -> 0 | M22: =E22 -> 0 | N22: =F22 -> 0 | O22: =G22 -> 0 | Q22: =I22 -> Equipment Sales | R22: =B22 -> 0 | T22: =D22 -> 0 | U22: =E22 -> 0 | V22: =F22 -> 0 | W22: =G22 -> 0
A23: Total Revenue | D23: =SUM(D14:D22) -> 1.2560567e+09 | E23: =SUM(E14:E22) -> 1.1989157e+09 | F23: =SUM(F14:F22) -> 1.2588614e+09 | G23: =SUM(G14:G22) -> 1.3218045e+09 | I23: =A23 -> Total Revenue | L23: =SUM(L14:L22) -> 1.2560567e+09 | M23: =SUM(M14:M22) -> 1.1989157e+09 | N23: =SUM(N14:N22) -> 1.2588614e+09 | O23: =SUM(O14:O22) -> 1.3218045e+09 | Q23: =I23 -> Total Revenue | T23: =SUM(T14:T22) -> 1.2560567e+09 | U23: =SUM(U14:U22) -> 1.1989157e+09 | V23: =SUM(V14:V22) -> 1.2588614e+09 | W23: =SUM(W14:W22) -> 1.3218045e+09
A25: Variable Costs | B25: NRC | C25: RC | I25: =A25 -> Variable Costs | J25: NRC | K25: RC | Q25: =A25 -> Variable Costs | R25: NRC | S25: RC
A26: =A14 -> Product 1 Customer Activation | B26: =SUM(Inputs!C143:C146) -> 69.55 | D26: =(D50+D55)*$B26 -> 1.4837333e+08 | E26: =E60*$B26 -> 38252500 | F26: =F60*$B26 -> 40165125 | G26: =G60*$B26 -> 42173381 | I26: =I7&" Monthly Cost" -> Product 1 Monthly Cost | K26: =Inputs!C165 -> 14.6925 | L26: =12*L7*$K$26 -> 3.76128e+08 | M26: =12*M7*$K$26 -> 3.949344e+08 | N26: =12*N7*$K$26 -> 4.1468112e+08 | O26: =12*O7*$K$26 -> 4.3541518e+08 | Q26: =Q7 -> Product 1
A27: =A15 -> Product 2 Customer Activation | B27: =SUM(Inputs!D143:D146) -> 69.55 | D27: =(D51+D56)*$B27 -> 18546667 | E27: =(E51+E56)*$B27 -> 2782000 | F27: =(F51+F56)*$B27 -> 2921100 | G27: =(G51+G56)*$B27 -> 3067155 | I27: =I8&" Monthly Cost" -> Product 2 Monthly Cost | K27: =Inputs!D165 -> 13.9425 | L27: =12*L8*$K$27 -> 44616000 | M27: =12*M8*$K$27 -> 46846800 | N27: =12*N8*$K$27 -> 49189140 | O27: =12*O8*$K$27 -> 51648597 | Q27: =Inputs!B143 -> Equipment Cost | R27: =Inputs!C143 -> 42 | T27: =(D$50+D$55)*$R$27 -> 89600000 | U27: =(E$50+E$55)*$R$27 -> 13440000 | V27: =(F$50+F$55)*$R$27 -> 14112000 | W27: =(G$50+G$55)*$R$27 -> 14817600
A28: =A16 -> Product 3 Customer Activation | B28: =SUM(Inputs!E143:E146) -> 69.55 | D28: =(D52+D57)*$B28 -> 18546667 | E28: =(E52+E57)*$B28 -> 2782000 | F28: =(F52+F57)*$B28 -> 2921100 | G28: =(G52+G57)*$B28 -> 3067155 | I28: =I9&" Monthly Cost" -> Product 3 Monthly Cost | K28: =Inputs!E165 -> 13.1925 | L28: =12*L9*$K$28 -> 42216000 | M28: =12*M9*$K$28 -> 44326800 | N28: =12*N9*$K$28 -> 46543140 | O28: =12*O9*$K$28 -> 48870297 | Q28: =Inputs!B144 -> Shipping Cost | R28: =Inputs!C144 -> 3 | T28: =(D$50+D$55)*$R$28 -> 6400000 | U28: =(E$50+E$55)*$R$28 -> 960000 | V28: =(F$50+F$55)*$R$28 -> 1008000 | W28: =(G$50+G$55)*$R$28 -> 1058400
A29: =A17 -> Prodcut 4 Customer Activation | B29: =SUM(Inputs!F143:F146) -> 70.92 | D29: =(D53+D58)*$B29 -> 70920000 | E29: =(E53+E58)*$B29 -> 10638000 | F29: =(F53+F58)*$B29 -> 11169900 | G29: =(G53+G58)*$B29 -> 11728395 | I29: =I10&" Monthly Cost" -> Prodcut 4 Monthly Cost | K29: =Inputs!F165 -> 29.646667 | L29: =12*L10*$K$29 -> 3.5576e+08 | M29: =12*M10*$K$29 -> 3.73548e+08 | N29: =12*N10*$K$29 -> 3.922254e+08 | O29: =12*O10*$K$29 -> 4.1183667e+08 | Q29: =Inputs!B145 -> Activation Commission | R29: =Inputs!C145 -> 20 | T29: =(D$50+D$55)*$R$29 -> 42666667 | U29: =(E$50+E$55)*$R$29 -> 6400000 | V29: =(F$50+F$55)*$R$29 -> 6720000 | W29: =(G$50+G$55)*$R$29 -> 7056000
A30: =A7&" Residual Commission" -> Product 1 Residual Commission | C30: =Inputs!C147 -> 0.15 | D30: =$C30*D18 -> 76608000 | E30: =$C30*E18 -> 80438400 | F30: =$C30*F18 -> 84460320 | G30: =$C30*G18 -> 88683336 | I30: Total Costs | L30: =SUM(L26:L29) -> 8.1872e+08 | M30: =SUM(M26:M29) -> 8.59656e+08 | N30: =SUM(N26:N29) -> 9.026388e+08 | O30: =SUM(O26:O29) -> 9.4777074e+08 | Q30: =Inputs!B146 -> Billing, Office, Bad Debt | R30: =Inputs!C146 -> 4.55 | T30: =(D$50+D$55)*$R$30 -> 9706666.7 | U30: =(E$50+E$55)*$R$30 -> 1456000 | V30: =(F$50+F$55)*$R$30 -> 1528800 | W30: =(G$50+G$55)*$R$30 -> 1605240
A31: =A8&" Residual Commission" -> Product 2 Residual Commission | C31: =Inputs!D147 -> 0.15 | D31: =$C31*D19 -> 7176000 | E31: =$C31*E19 -> 7534800 | F31: =$C31*F19 -> 7911540 | G31: =$C31*G19 -> 8307117 | Q31: =Inputs!B147 -> Recurring Commission | S31: =Inputs!C147 -> 0.15 | T31: =$S$31*T18 -> 76608000 | U31: =$S$31*U18 -> 80438400 | V31: =$S$31*V18 -> 84460320 | W31: =$S$31*W18 -> 88683336
A32: =A9&" Residual Commission" -> Product 3 Residual Commission | C32: =Inputs!E147 -> 0.15 | D32: =$C32*D20 -> 4776000 | E32: =$C32*E20 -> 5014800 | F32: =$C32*F20 -> 5265540 | G32: =$C32*G20 -> 5528817 | I32: =A40 -> Total EBITDA | L32: =L23-L30 -> 4.3733667e+08 | M32: =M23-M30 -> 3.3925967e+08 | N32: =N23-N30 -> 3.5622265e+08 | O32: =O23-O30 -> 3.7403378e+08 | Q32: =Inputs!B148 -> Wholesale Provider Cost | S32: =Inputs!C148 -> 5.55 | T32: =$S$32*T7*12 -> 1.4208e+08 | U32: =$S$32*U7*12 -> 1.49184e+08 | V32: =$S$32*V7*12 -> 1.566432e+08 | W32: =$S$32*W7*12 -> 1.6447536e+08
A33: =A10&" Residual Commission" -> Prodcut 4 Residual Commission | C33: =Inputs!F147 -> 0.15 | D33: =$C33*D21 -> 80910000 | E33: =$C33*E21 -> 84955500 | F33: =$C33*F21 -> 89203275 | G33: =$C33*G21 -> 93663439 | Q33: =Inputs!B149 -> Marketing Expense | S33: =Inputs!C149 -> 3 | T33: =$S$33*T7 -> 6400000 | U33: =$S$33*U7 -> 6720000 | V33: =$S$33*V7 -> 7056000 | W33: =$S$33*W7 -> 7408800
A34: =A7&" Operating Cost" -> Product 1 Operating Cost | C34: =Inputs!C163 -> 8.8966667 | D34: =D7*$C$34*12 -> 2.2775467e+08 | E34: =E7*$C$34*12 -> 2.391424e+08 | F34: =F7*$C$34*12 -> 2.5109952e+08 | G34: =G7*$C$34*12 -> 2.636545e+08 | L34: =D42 -> Monthly Figures | Q34: =Inputs!B150 -> Sales and General Administrative | S34: =Inputs!C150 -> 1 | T34: =$S$34*T7 -> 2133333.3 | U34: =$S$34*U7 -> 2240000 | V34: =$S$34*V7 -> 2352000 | W34: =$S$34*W7 -> 2469600
A35: =A8&" Operating Cost" -> Product 2 Operating Cost | C35: =Inputs!D163 -> 8.1466667 | D35: =D8*$C$34*12 -> 28469333 | E35: =E8*$C$34*12 -> 29892800 | F35: =F8*$C$34*12 -> 31387440 | G35: =G8*$C$34*12 -> 32956812 | L35: =D43 -> ARPU | M35: =E43 -> AVG COST | N35: =F43 -> Gross margin | O35: =G43 -> Margin | Q35: =Inputs!B151 -> Occupancy | S35: =Inputs!C151 -> 0.25 | T35: =$S$35*T7 -> 533333.33 | U35: =$S$35*U7 -> 560000 | V35: =$S$35*V7 -> 588000 | W35: =$S$35*W7 -> 617400
A36: =A9&" Operating Cost" -> Product 3 Operating Cost | C36: =Inputs!E163 -> 7.3966667 | D36: =D9*$C$34*12 -> 28469333 | E36: =E9*$C$34*12 -> 29892800 | F36: =F9*$C$34*12 -> 31387440 | G36: =G9*$C$34*12 -> 32956812 | L36: =D44 -> 26.552901 | M36: =(SUM(L30:O30)/4/12)/(SUM(L11:O11)/4) -> 18.607272 | N36: =L36-M36 -> 7.9456287 | O36: =N36/L36 -> 0.29923769 | Q36: =Q8 -> Product 2
A37: =A10&" Operating Cost" -> Prodcut 4 Operating Cost | C37: =Inputs!F163 -> 23.736667 | D37: =D10*$C$34*12 -> 1.0676e+08 | E37: =E10*$C$34*12 -> 1.12098e+08 | F37: =F10*$C$34*12 -> 1.177029e+08 | G37: =G10*$C$34*12 -> 1.2358805e+08 | Q37: =Q27 -> Equipment Cost | R37: =Inputs!D143 -> 42 | T37: =(D$51+D$56)*$R37 -> 11200000 | U37: =(E$51+E$56)*$R37 -> 1680000 | V37: =(F$51+F$56)*$R37 -> 1764000 | W37: =(G$51+G$56)*$R37 -> 1852200
A38: Total Costs | D38: =SUM(D26:D37) -> 8.1731e+08 | E38: =SUM(E26:E37) -> 6.43424e+08 | F38: =SUM(F26:F37) -> 6.755952e+08 | G38: =SUM(G26:G37) -> 7.0937496e+08 | I38: =A46 -> *Subscriber number assumes a monthly customer churn rate of 5% | Q38: =Q28 -> Shipping Cost | R38: =Inputs!D144 -> 3 | T38: =(D$51+D$56)*$R38 -> 800000 | U38: =(E$51+E$56)*$R38 -> 120000 | V38: =(F$51+F$56)*$R38 -> 126000 | W38: =(G$51+G$56)*$R38 -> 132300
Q39: =Q29 -> Activation Commission | R39: =Inputs!D145 -> 20 | T39: =(D$51+D$56)*$R39 -> 5333333.3 | U39: =(E$51+E$56)*$R39 -> 800000 | V39: =(F$51+F$56)*$R39 -> 840000 | W39: =(G$51+G$56)*$R39 -> 882000
A40: Total EBITDA | D40: =D23-D38 -> 4.3874667e+08 | E40: =E23-E38 -> 5.5549167e+08 | F40: =F23-F38 -> 5.8326625e+08 | G40: =G23-G38 -> 6.1242956e+08 | Q40: =Q30 -> Billing, Office, Bad Debt | R40: =Inputs!D146 -> 4.55 | T40: =(D$51+D$56)*$R40 -> 1213333.3 | U40: =(E$51+E$56)*$R40 -> 182000 | V40: =(F$51+F$56)*$R40 -> 191100 | W40: =(G$51+G$56)*$R40 -> 200655
Q41: =Q31 -> Recurring Commission | S41: =Inputs!D147 -> 0.15 | T41: =$S$41*T19 -> 7176000 | U41: =$S$41*U19 -> 7534800 | V41: =$S$41*V19 -> 7911540 | W41: =$S$41*W19 -> 8307117
D42: Monthly Figures | I42: =SUM(D23:G23) -> 5035638306 | J42: Chart 1 Revenue | M42: Chart 1 Margin | N42: =G44 -> 0.4348871 | Q42: =Q32 -> Wholesale Provider Cost | S42: =Inputs!D148 -> 5.55 | T42: =12*T8*$S$42 -> 17760000 | U42: =12*U8*$S$42 -> 18648000 | V42: =12*V8*$S$42 -> 19580400 | W42: =12*W8*$S$42 -> 20559420
...

Sheet Entity 3 Out
A1: Entity 3
A2: Revenue and Costs
A3: Base Case Projection
A5: Product Type 1 | C5: 2008-2009 | D5: 2009-2010 | E5: 2010-2011 | F5: 2011-2012
A6: Product 1 | C6: =Inputs!C170 -> 100 | D6: =C6+Inputs!D170 -> 150 | E6: =D6+Inputs!D170 -> 200 | F6: =E6+Inputs!D170 -> 250
A7: Product 2 | C7: =Inputs!C171 -> 150 | D7: =C7+Inputs!D171 -> 200 | E7: =D7+Inputs!D171 -> 250 | F7: =E7+Inputs!D171 -> 300
A8: Product 3 | C8: =Inputs!C172 -> 125 | D8: =C8+Inputs!D172 -> 175 | E8: =D8+Inputs!D172 -> 225 | F8: =E8+Inputs!D172 -> 275
A9: Total Subscribers | C9: =SUM(C6:C8) -> 375 | D9: =SUM(D6:D8) -> 525 | E9: =SUM(E6:E8) -> 675 | F9: =SUM(F6:F8) -> 825
A11: Revenue | B11: Monthly
A12: =A6&" at" -> Product 1 at | B12: =Inputs!E170 -> 3750 | C12: =$B12*C6 -> 375000 | D12: =$B12*D6 -> 562500 | E12: =$B12*E6 -> 750000 | F12: =$B12*F6 -> 937500
A13: =A7&" at" -> Product 2 at | B13: =Inputs!E171 -> 44.95 | C13: =$B13*C7 -> 6742.5 | D13: =$B13*D7 -> 8990 | E13: =$B13*E7 -> 11237.5 | F13: =$B13*F7 -> 13485
A14: =A8&" at" -> Product 3 at | B14: =Inputs!E172 -> 0 | C14: =$B14*C8 -> 0 | D14: =$B14*D8 -> 0 | E14: =$B14*E8 -> 0 | F14: =$B14*F8 -> 0
A15: Total Revenue | C15: =SUM(C12:C14) -> 381742.5 | D15: =SUM(D12:D14) -> 571490 | E15: =SUM(E12:E14) -> 761237.5 | F15: =SUM(F12:F14) -> 950985
A17: Cost of Goods
A18: =A12 -> Product 1 at | B18: =Inputs!F170 -> 3071.25 | C18: =$B18*C6 -> 307125 | D18: =$B18*D6 -> 460687.5 | E18: =$B18*E6 -> 614250 | F18: =$B18*F6 -> 767812.5
A19: =A13 -> Product 2 at | B19: =Inputs!F171 -> 32.0375 | C19: =$B19*C7 -> 4805.625 | D19: =$B19*D7 -> 6407.5 | E19: =$B19*E7 -> 8009.375 | F19: =$B19*F7 -> 9611.25
A20: =A14 -> Product 3 at | B20: =Inputs!F172 -> 0 | C20: =$B20*C8 -> 0 | D20: =$B20*D8 -> 0 | E20: =$B20*E8 -> 0 | F20: =$B20*F8 -> 0
A21: Total Cost of Goods | C21: =SUM(C18:C20) -> 311930.62 | D21: =SUM(D18:D20) -> 467095 | E21: =SUM(E18:E20) -> 622259.38 | F21: =SUM(F18:F20) -> 777423.75
A23: Operating Expenses | B23: Per Sub
A24: =Inputs!B174&"*" -> Sales and Marketing* | B24: =Inputs!C174 -> 45 | C24: =C9*$B24+Inputs!D174 -> 21875 | D24: =D9*$B24 -> 23625 | E24: =E9*$B24 -> 30375 | F24: =F9*$B24 -> 37125
A25: =Inputs!B175 -> General Administrative | B25: =Inputs!C175 -> 45 | C25: =C10*$B25 -> 0 | D25: =D10*$B25 -> 0 | E25: =E10*$B25 -> 0 | F25: =F10*$B25 -> 0
A26: =Inputs!B176 -> Occupancy | B26: =Inputs!C176 -> 45 | C26: =C11*$B26 -> 0 | D26: =D11*$B26 -> 0 | E26: =E11*$B26 -> 0 | F26: =F11*$B26 -> 0
A27: Total Operating Expenses | C27: =SUM(C24:C26) -> 21875 | D27: =SUM(D24:D26) -> 23625 | E27: =SUM(E24:E26) -> 30375 | F27: =SUM(F24:F26) -> 37125
A29: Total EBITDA | C29: =C15-C21-C27 -> 47936.875 | D29: =D15-D21-D27 -> 80770 | E29: =E15-E21-E27 -> 108603.12 | F29: =F15-F21-F27 -> 136436.25
A31: ="*An additional $"&Inputs!D174&" is included in year 1 for launch marketing." -> *An additional $5000 is included in year 1 for launch marketing.

Sheet Summary
A1: Based on Output #1 | H1: Based on Output #2 | O1: Based on Output #3 | V1: Based on Output #4
A2: All Three Entities | H2: =A2 -> All Three Entities | O2: =H2 -> All Three Entities | V2: =O2 -> All Three Entities
A3: Projected Operational Summary | H3: Projected Operational Summary | O3: Projected Operational Summary | V3: Projected Operational Summary
A5: Subscribers | C5: 2008-2009 | D5: 2009-2010 | E5: 2010-2011 | F5: 2011-2012 | H5: Subscribers | J5: 2008-2009 | K5: 2009-2010 | L5: 2010-2011 | M5: 2011-2012 | O5: Subscribers | Q5: 2008-2009 | R5: 2009-2010 | S5: 2010-2011 | T5: 2011-2012 | V5: Subscribers | X5: 2008-2009 | Y5: 2009-2010 | Z5: 2010-2011 | AA5: 2011-2012
A6: Entity 1 | H6: =A6 -> Entity 1 | O6: =H6 -> Entity 1 | V6: =O6 -> Entity 1
B7: ='Entity 1 Outputs'!I7 -> Brand 1 | C7: ='Entity 1 Outputs'!L7 -> 15000 | D7: ='Entity 1 Outputs'!M7 -> 21750 | E7: ='Entity 1 Outputs'!N7 -> 31537.5 | F7: ='Entity 1 Outputs'!O7 -> 45729.375 | I7: =B7 -> Brand 1 | J7: =C7 -> 15000 | K7: =D7 -> 21750 | L7: =E7 -> 31537.5 | M7: =F7 -> 45729.375 | P7: =B7 -> Brand 1 | Q7: =C7 -> 15000 | R7: =D7 -> 21750 | S7: =E7 -> 31537.5 | T7: =F7 -> 45729.375 | W7: =I7 -> Brand 1 | X7: =J7 -> 15000 | Y7: =K7 -> 21750 | Z7: =L7 -> 31537.5 | AA7: =M7 -> 45729.375
B8: ='Entity 1 Outputs'!I8 -> Brand 2 | C8: ='Entity 1 Outputs'!L8 -> 10000 | D8: ='Entity 1 Outputs'!M8 -> 14500 | E8: ='Entity 1 Outputs'!N8 -> 21025 | F8: ='Entity 1 Outputs'!O8 -> 30486.25 | I8: =B8 -> Brand 2 | J8: =C8 -> 10000 | K8: =D8 -> 14500 | L8: =E8 -> 21025 | M8: =F8 -> 30486.25 | P8: =B8 -> Brand 2 | Q8: =C8 -> 10000 | R8: =D8 -> 14500 | S8: =E8 -> 21025 | T8: =F8 -> 30486.25 | W8: =I8 -> Brand 2 | X8: =J8 -> 10000 | Y8: =K8 -> 14500 | Z8: =L8 -> 21025 | AA8: =M8 -> 30486.25
B9: ='Entity 1 Outputs'!I9 -> Brand 3 | C9: ='Entity 1 Outputs'!L9 -> 5000 | D9: ='Entity 1 Outputs'!M9 -> 7250 | E9: ='Entity 1 Outputs'!N9 -> 10512.5 | F9: ='Entity 1 Outputs'!O9 -> 15243.125 | I9: =B9 -> Brand 3 | J9: =C9 -> 5000 | K9: =D9 -> 7250 | L9: =E9 -> 10512.5 | M9: =F9 -> 15243.125 | P9: =B9 -> Brand 3 | Q9: =C9 -> 5000 | R9: =D9 -> 7250 | S9: =E9 -> 10512.5 | T9: =F9 -> 15243.125 | W9: =I9 -> Brand 3 | X9: =J9 -> 5000 | Y9: =K9 -> 7250 | Z9: =L9 -> 10512.5 | AA9: =M9 -> 15243.125
B10: ='Entity 1 Outputs'!I10 -> Brand 4 | C10: ='Entity 1 Outputs'!L10 -> 5000 | D10: ='Entity 1 Outputs'!M10 -> 7250 | E10: ='Entity 1 Outputs'!N10 -> 10512.5 | F10: ='Entity 1 Outputs'!O10 -> 15243.125 | I10: =B10 -> Brand 4 | J10: =C10 -> 5000 | K10: =D10 -> 7250 | L10: =E10 -> 10512.5 | M10: =F10 -> 15243.125 | P10: =B10 -> Brand 4 | Q10: =C10 -> 5000 | R10: =D10 -> 7250 | S10: =E10 -> 10512.5 | T10: =F10 -> 15243.125 | W10: =I10 -> Brand 4 | X10: =J10 -> 5000 | Y10: =K10 -> 7250 | Z10: =L10 -> 10512.5 | AA10: =M10 -> 15243.125
B11: ='Entity 1 Outputs'!I11 -> Brand 5 | C11: ='Entity 1 Outputs'!L11 -> 5000 | D11: ='Entity 1 Outputs'!M11 -> 7250 | E11: ='Entity 1 Outputs'!N11 -> 10512.5 | F11: ='Entity 1 Outputs'!O11 -> 15243.125 | I11: =B11 -> Brand 5 | J11: =C11 -> 5000 | K11: =D11 -> 7250 | L11: =E11 -> 10512.5 | M11: =F11 -> 15243.125 | P11: =B11 -> Brand 5 | Q11: =C11 -> 5000 | R11: =D11 -> 7250 | S11: =E11 -> 10512.5 | T11: =F11 -> 15243.125 | W11: =I11 -> Brand 5 | X11: =J11 -> 5000 | Y11: =K11 -> 7250 | Z11: =L11 -> 10512.5 | AA11: =M11 -> 15243.125
B12: ='Entity 1 Outputs'!I12 -> Brand 6 | C12: ='Entity 1 Outputs'!L12 -> 5000 | D12: ='Entity 1 Outputs'!M12 -> 7250 | E12: ='Entity 1 Outputs'!N12 -> 10512.5 | F12: ='Entity 1 Outputs'!O12 -> 15243.125 | I12: =B12 -> Brand 6 | J12: =C12 -> 5000 | K12: =D12 -> 7250 | L12: =E12 -> 10512.5 | M12: =F12 -> 15243.125 | P12: =B12 -> Brand 6 | Q12: =C12 -> 5000 | R12: =D12 -> 7250 | S12: =E12 -> 10512.5 | T12: =F12 -> 15243.125 | W12: =I12 -> Brand 6 | X12: =J12 -> 5000 | Y12: =K12 -> 7250 | Z12: =L12 -> 10512.5 | AA12: =M12 -> 15243.125
B13: ='Entity 1 Outputs'!I13 -> Brand 7 | C13: ='Entity 1 Outputs'!L13 -> 869.18 | D13: ='Entity 1 Outputs'!M13 -> 1260.311 | E13: ='Entity 1 Outputs'!N13 -> 1827.4509 | F13: ='Entity 1 Outputs'!O13 -> 2649.8039 | I13: =B13 -> Brand 7 | J13: =C13 -> 869.18 | K13: =D13 -> 1260.311 | L13: =E13 -> 1827.4509 | M13: =F13 -> 2649.8039 | P13: =B13 -> Brand 7 | Q13: =C13 -> 869.18 | R13: =D13 -> 1260.311 | S13: =E13 -> 1827.4509 | T13: =F13 -> 2649.8039 | W13: =I13 -> Brand 7 | X13: =J13 -> 869.18 | Y13: =K13 -> 1260.311 | Z13: =L13 -> 1827.4509 | AA13: =M13 -> 2649.8039
B14: ='Entity 1 Outputs'!I14 -> Brand 8 | C14: ='Entity 1 Outputs'!L14 -> 5000 | D14: ='Entity 1 Outputs'!M14 -> 7250 | E14: ='Entity 1 Outputs'!N14 -> 10512.5 | F14: ='Entity 1 Outputs'!O14 -> 15243.125 | I14: =B14 -> Brand 8 | J14: =C14 -> 5000 | K14: =D14 -> 7250 | L14: =E14 -> 10512.5 | M14: =F14 -> 15243.125 | P14: =B14 -> Brand 8 | Q14: =C14 -> 5000 | R14: =D14 -> 7250 | S14: =E14 -> 10512.5 | T14: =F14 -> 15243.125 | W14: =I14 -> Brand 8 | X14: =J14 -> 5000 | Y14: =K14 -> 7250 | Z14: =L14 -> 10512.5 | AA14: =M14 -> 15243.125
B15: ='Entity 1 Outputs'!I15 -> Brand 9 | C15: ='Entity 1 Outputs'!L15 -> 5000 | D15: ='Entity 1 Outputs'!M15 -> 7250 | E15: ='Entity 1 Outputs'!N15 -> 10512.5 | F15: ='Entity 1 Outputs'!O15 -> 15243.125 | I15: =B15 -> Brand 9 | J15: =C15 -> 5000 | K15: =D15 -> 7250 | L15: =E15 -> 10512.5 | M15: =F15 -> 15243.125 | P15: =B15 -> Brand 9 | Q15: =C15 -> 5000 | R15: =D15 -> 7250 | S15: =E15 -> 10512.5 | T15: =F15 -> 15243.125 | W15: =I15 -> Brand 9 | X15: =J15 -> 5000 | Y15: =K15 -> 7250 | Z15: =L15 -> 10512.5 | AA15: =M15 -> 15243.125
